Workbook
Name Be: [1]lists!$B$4:$B$10
Name Bu: [1]lists!$C$4:$C$31
Name Cz: [1]lists!$D$4:$D$17
Name dw: [2]lists!$D$4:$D$17
Name dwqdf: [2]lists!$C$4:$C$31
Name fedf: [2]lists!$G$4:$G$19
Name H: #REF!
Name Hu: [1]lists!$E$4:$E$10
Name I: #REF!
Name J: #REF!
Name Ka: [1]lists!$F$4:$F$19
Name Po: [1]lists!$G$4:$G$19
Name Ro: [1]lists!$H$4:$H$11
Name Ru: [1]lists!$I$4:$I$83
Name Sl: [1]lists!$J$4:$J$11
Name Slo: [1]lists!$K$4:$K$15
Name Uk: [1]lists!$L$4:$L$30

Sheet About PMR

Sheet Table of contents
B2: Table of contents
B3: About PMR
B4: Summary
B5: Poland
B6: Austria
B7: Czech Republic
B8: Greece
B9: Hungary
B10: Slovakia
B11: Croatia
B12: Vertical split
B13: Methodology
B14: Contacts details

Sheet Summary
A1: Year | B1: 2016 | C1: 2017 | D1: 2018 | E1: 2019 | F1: 2020 | G1: 2021 | H1: 2022 | I1: 2023 | J1: 2024 | K1: 2025e | L1: 2026f | M1: 2027f | N1: 2028f | O1: 2029f | P1: 2030f | R1: CAGR 2019-2024 | S1: CAGR 2025-2030
A2: Total IT market size (€ m) | B2: =B4+B6+B8 -> 31193.545 | C2: =C4+C6+C8 -> 32481.585 | D2: =D4+D6+D8 -> 34111.969 | E2: =E4+E6+E8 -> 36196.393 | F2: =F4+F6+F8 -> 36922.215 | G2: =G4+G6+G8 -> 40349.6 | H2: =H4+H6+H8 -> 43024.99 | I2: =I4+I6+I8 -> 46287.696 | ... P2: =P4+P6+P8 -> 71249.507 | R2: =(J2/D2)^(1/6)-1 -> 0.069020871 | S2: =(P2/J2)^(1/6)-1 -> 0.0576119
A3: Growth rate (%) | C3: =C2/B2-1 -> 0.041291894 | D3: =D2/C2-1 -> 0.050194079 | E3: =E2/D2-1 -> 0.061105353 | F3: =F2/E2-1 -> 0.020052342 | G3: =G2/F2-1 -> 0.09282718 | H3: =H2/G2-1 -> 0.06630523 | I3: =I2/H2-1 -> 0.075832809 | J3: =J2/I2-1 -> 0.099912987 | ... P3: =P2/O2-1 -> 0.053891031
A4: Software | B4: =Poland!B4+Austria!B4+'Czech Republic'!B4+Greece!B4+Hungary!B4+Slovakia!B4+Croatia!B4 -> 6022.6998 | C4: =Poland!C4+Austria!C4+'Czech Republic'!C4+Greece!C4+Hungary!C4+Slovakia!C4+Croatia!C4 -> 6331.3662 | D4: =Poland!D4+Austria!D4+'Czech Republic'!D4+Greece!D4+Hungary!D4+Slovakia!D4+Croatia!D4 -> 6648.8056 | E4: =Poland!E4+Austria!E4+'Czech Republic'!E4+Greece!E4+Hungary!E4+Slovakia!E4+Croatia!E4 -> 7057.8692 | F4: =Poland!F4+Austria!F4+'Czech Republic'!F4+Greece!F4+Hungary!F4+Slovakia!F4+Croatia!F4 -> 7366.2936 | G4: =Poland!G4+Austria!G4+'Czech Republic'!G4+Greece!G4+Hungary!G4+Slovakia!G4+Croatia!G4 -> 7780.2696 | H4: =Poland!H4+Austria!H4+'Czech Republic'!H4+Greece!H4+Hungary!H4+Slovakia!H4+Croatia!H4 -> 8294.5214 | I4: =Poland!I4+Austria!I4+'Czech Republic'!I4+Greece!I4+Hungary!I4+Slovakia!I4+Croatia!I4 -> 9130.7545 | ... P4: =Poland!P4+Austria!P4+'Czech Republic'!P4+Greece!P4+Hungary!P4+Slovakia!P4+Croatia!P4 -> 15041.211 | R4: =(J4/D4)^(1/6)-1 -> 0.072809641 | S4: =(P4/J4)^(1/6)-1 -> 0.067990016
A5: Growth rate (%) | C5: =C4/B4-1 -> 0.051250511 | D5: =D4/C4-1 -> 0.050137591 | E5: =E4/D4-1 -> 0.061524372 | F5: =F4/E4-1 -> 0.043699358 | G5: =G4/F4-1 -> 0.056198686 | H5: =H4/G4-1 -> 0.066096906 | I5: =I4/H4-1 -> 0.10081753 | J5: =J4/I4-1 -> 0.1101278 | ... P5: =P4/O4-1 -> 0.066949335
A6: Hardware | B6: =Poland!B6+Austria!B6+'Czech Republic'!B6+Greece!B6+Hungary!B6+Slovakia!B6+Croatia!B6 -> 13086.818 | C6: =Poland!C6+Austria!C6+'Czech Republic'!C6+Greece!C6+Hungary!C6+Slovakia!C6+Croatia!C6 -> 13603.741 | D6: =Poland!D6+Austria!D6+'Czech Republic'!D6+Greece!D6+Hungary!D6+Slovakia!D6+Croatia!D6 -> 14433.702 | E6: =Poland!E6+Austria!E6+'Czech Republic'!E6+Greece!E6+Hungary!E6+Slovakia!E6+Croatia!E6 -> 15434.475 | F6: =Poland!F6+Austria!F6+'Czech Republic'!F6+Greece!F6+Hungary!F6+Slovakia!F6+Croatia!F6 -> 15654.028 | G6: =Poland!G6+Austria!G6+'Czech Republic'!G6+Greece!G6+Hungary!G6+Slovakia!G6+Croatia!G6 -> 18039.267 | H6: =Poland!H6+Austria!H6+'Czech Republic'!H6+Greece!H6+Hungary!H6+Slovakia!H6+Croatia!H6 -> 19105.111 | I6: =Poland!I6+Austria!I6+'Czech Republic'!I6+Greece!I6+Hungary!I6+Slovakia!I6+Croatia!I6 -> 20072.67 | ... P6: =Poland!P6+Austria!P6+'Czech Republic'!P6+Greece!P6+Hungary!P6+Slovakia!P6+Croatia!P6 -> 27882.995 | R6: =(J6/D6)^(1/6)-1 -> 0.072470336 | S6: =(P6/J6)^(1/6)-1 -> 0.04057884
A7: Growth rate (%) | C7: =C6/B6-1 -> 0.039499488 | D7: =D6/C6-1 -> 0.061009808 | E7: =E6/D6-1 -> 0.069335823 | F7: =F6/E6-1 -> 0.014224841 | G7: =G6/F6-1 -> 0.15237223 | H7: =H6/G6-1 -> 0.05908467 | I7: =I6/H6-1 -> 0.050643973 | J7: =J6/I6-1 -> 0.094168814 | ... P7: =P6/O6-1 -> 0.030646586
A8: Services | B8: =Poland!B8+Austria!B8+'Czech Republic'!B8+Greece!B8+Hungary!B8+Slovakia!B8+Croatia!B8 -> 12084.027 | C8: =Poland!C8+Austria!C8+'Czech Republic'!C8+Greece!C8+Hungary!C8+Slovakia!C8+Croatia!C8 -> 12546.478 | D8: =Poland!D8+Austria!D8+'Czech Republic'!D8+Greece!D8+Hungary!D8+Slovakia!D8+Croatia!D8 -> 13029.461 | E8: =Poland!E8+Austria!E8+'Czech Republic'!E8+Greece!E8+Hungary!E8+Slovakia!E8+Croatia!E8 -> 13704.048 | F8: =Poland!F8+Austria!F8+'Czech Republic'!F8+Greece!F8+Hungary!F8+Slovakia!F8+Croatia!F8 -> 13901.893 | G8: =Poland!G8+Austria!G8+'Czech Republic'!G8+Greece!G8+Hungary!G8+Slovakia!G8+Croatia!G8 -> 14530.063 | H8: =Poland!H8+Austria!H8+'Czech Republic'!H8+Greece!H8+Hungary!H8+Slovakia!H8+Croatia!H8 -> 15625.357 | I8: =Poland!I8+Austria!I8+'Czech Republic'!I8+Greece!I8+Hungary!I8+Slovakia!I8+Croatia!I8 -> 17084.271 | ... P8: =Poland!P8+Austria!P8+'Czech Republic'!P8+Greece!P8+Hungary!P8+Slovakia!P8+Croatia!P8 -> 28325.3 | R8: =(J8/D8)^(1/6)-1 -> 0.063137749 | S8: =(P8/J8)^(1/6)-1 -> 0.070578397
A9: Growth rate (%) | C9: =C8/B8-1 -> 0.038269653 | D9: =D8/C8-1 -> 0.03849544 | E9: =E8/D8-1 -> 0.051774027 | F9: =F8/E8-1 -> 0.014436985 | G9: =G8/F8-1 -> 0.045185921 | H9: =H8/G8-1 -> 0.075381199 | I9: =I8/H8-1 -> 0.093368361 | J9: =J8/I8-1 -> 0.10120259 | ... P9: =P8/O8-1 -> 0.070703234
A11: Smartphones market size (€ m) | B11: =Poland!B11+Austria!B11+'Czech Republic'!B11+Greece!B11+Hungary!B11+Slovakia!B11+Croatia!B11 -> 5000.2985 | C11: =Poland!C11+Austria!C11+'Czech Republic'!C11+Greece!C11+Hungary!C11+Slovakia!C11+Croatia!C11 -> 5198.2324 | D11: =Poland!D11+Austria!D11+'Czech Republic'!D11+Greece!D11+Hungary!D11+Slovakia!D11+Croatia!D11 -> 5562.3409 | E11: =Poland!E11+Austria!E11+'Czech Republic'!E11+Greece!E11+Hungary!E11+Slovakia!E11+Croatia!E11 -> 6050.2573 | F11: =Poland!F11+Austria!F11+'Czech Republic'!F11+Greece!F11+Hungary!F11+Slovakia!F11+Croatia!F11 -> 5291.2075 | G11: =Poland!G11+Austria!G11+'Czech Republic'!G11+Greece!G11+Hungary!G11+Slovakia!G11+Croatia!G11 -> 6685.3091 | H11: =Poland!H11+Austria!H11+'Czech Republic'!H11+Greece!H11+Hungary!H11+Slovakia!H11+Croatia!H11 -> 6946.8631 | I11: =Poland!I11+Austria!I11+'Czech Republic'!I11+Greece!I11+Hungary!I11+Slovakia!I11+Croatia!I11 -> 7116.1743 | ... P11: =Poland!P11+Austria!P11+'Czech Republic'!P11+Greece!P11+Hungary!P11+Slovakia!P11+Croatia!P11 -> 9115.502 | R11: =(J11/D11)^(1/6)-1 -> 0.053236256 | S11: =(P11/J11)^(1/6)-1 -> 0.030927277
A12: Growth rate (%) | C12: =C11/B11-1 -> 0.039584403 | D12: =D11/C11-1 -> 0.070044685 | E12: =E11/D11-1 -> 0.087717814 | F12: =F11/E11-1 -> -0.12545744 | G12: =G11/F11-1 -> 0.26347513 | H12: =H11/G11-1 -> 0.039123683 | I12: =I11/H11-1 -> 0.024372333 | J12: =J11/I11-1 -> 0.067003467 | ... P12: =P11/O11-1 -> 0.021299493
A14: Cybersecurity market size (€ m) | B14: =Poland!B14+Austria!B14+'Czech Republic'!B14+Greece!B14+Hungary!B14+Slovakia!B14+Croatia!B14 -> 868.22291 | C14: =Poland!C14+Austria!C14+'Czech Republic'!C14+Greece!C14+Hungary!C14+Slovakia!C14+Croatia!C14 -> 951.50134 | D14: =Poland!D14+Austria!D14+'Czech Republic'!D14+Greece!D14+Hungary!D14+Slovakia!D14+Croatia!D14 -> 1073.345 | E14: =Poland!E14+Austria!E14+'Czech Republic'!E14+Greece!E14+Hungary!E14+Slovakia!E14+Croatia!E14 -> 1170.9903 | F14: =Poland!F14+Austria!F14+'Czech Republic'!F14+Greece!F14+Hungary!F14+Slovakia!F14+Croatia!F14 -> 1182.537 | G14: =Poland!G14+Austria!G14+'Czech Republic'!G14+Greece!G14+Hungary!G14+Slovakia!G14+Croatia!G14 -> 1271.5908 | H14: =Poland!H14+Austria!H14+'Czech Republic'!H14+Greece!H14+Hungary!H14+Slovakia!H14+Croatia!H14 -> 1465.6583 | I14: =Poland!I14+Austria!I14+'Czech Republic'!I14+Greece!I14+Hungary!I14+Slovakia!I14+Croatia!I14 -> 1645.9208 | ... P14: =Poland!P14+Austria!P14+'Czech Republic'!P14+Greece!P14+Hungary!P14+Slovakia!P14+Croatia!P14 -> 2930.1344 | R14: =(J14/D14)^(1/6)-1 -> 0.093405396 | S14: =(P14/J14)^(1/6)-1 -> 0.081210259
A15: Growth rate (%) | C15: =C14/B14-1 -> 0.095918259 | D15: =D14/C14-1 -> 0.12805407 | E15: =E14/D14-1 -> 0.090972974 | F15: =F14/E14-1 -> 0.009860593 | G15: =G14/F14-1 -> 0.075307376 | H15: =H14/G14-1 -> 0.15261794 | I15: =I14/H14-1 -> 0.1229908 | J15: =J14/I14-1 -> 0.11433985 | ... P15: =P14/O14-1 -> 0.079120666
A17: Enterprises (by size) (number of enterprises in thousands)
A18: Microenterprises (0-9 employees) | B18: =Poland!B18+Austria!B18+'Czech Republic'!B18+Greece!B18+Hungary!B18+Slovakia!B18+Croatia!B18 -> 3838.5999 | C18: =Poland!C18+Austria!C18+'Czech Republic'!C18+Greece!C18+Hungary!C18+Slovakia!C18+Croatia!C18 -> 3830.8917 | D18: =Poland!D18+Austria!D18+'Czech Republic'!D18+Greece!D18+Hungary!D18+Slovakia!D18+Croatia!D18 -> 3878.4667 | E18: =Poland!E18+Austria!E18+'Czech Republic'!E18+Greece!E18+Hungary!E18+Slovakia!E18+Croatia!E18 -> 4016.7657 | F18: =Poland!F18+Austria!F18+'Czech Republic'!F18+Greece!F18+Hungary!F18+Slovakia!F18+Croatia!F18 -> 4069.4619 | G18: =Poland!G18+Austria!G18+'Czech Republic'!G18+Greece!G18+Hungary!G18+Slovakia!G18+Croatia!G18 -> 4306.4773 | H18: =Poland!H18+Austria!H18+'Czech Republic'!H18+Greece!H18+Hungary!H18+Slovakia!H18+Croatia!H18 -> 4497.7475 | I18: =Poland!I18+Austria!I18+'Czech Republic'!I18+Greece!I18+Hungary!I18+Slovakia!I18+Croatia!I18 -> 4521.2448 | ... P18: =Poland!P18+Austria!P18+'Czech Republic'!P18+Greece!P18+Hungary!P18+Slovakia!P18+Croatia!P18 -> 4920.1701 | R18: =(J18/D18)^(1/6)-1 -> 0.027111084 | S18: =(P18/J18)^(1/6)-1 -> 0.012984014
A19: Growth rate (%) | C19: =C18/B18-1 -> -0.0020080644 | D19: =D18/C18-1 -> 0.012418787 | E19: =E18/D18-1 -> 0.035658163 | F19: =F18/E18-1 -> 0.013119048 | G19: =G18/F18-1 -> 0.058242462 | H19: =H18/G18-1 -> 0.044414526 | I19: =I18/H18-1 -> 0.0052242439 | J19: =J18/I18-1 -> 0.0071787225 | ... P19: =P18/O18-1 -> 0.011609494
A20: SME (10-249 employees) | B20: =Poland!B20+Austria!B20+'Czech Republic'!B20+Greece!B20+Hungary!B20+Slovakia!B20+Croatia!B20 -> 310.09102 | C20: =Poland!C20+Austria!C20+'Czech Republic'!C20+Greece!C20+Hungary!C20+Slovakia!C20+Croatia!C20 -> 320.00879 | D20: =Poland!D20+Austria!D20+'Czech Republic'!D20+Greece!D20+Hungary!D20+Slovakia!D20+Croatia!D20 -> 326.92679 | E20: =Poland!E20+Austria!E20+'Czech Republic'!E20+Greece!E20+Hungary!E20+Slovakia!E20+Croatia!E20 -> 333.34971 | F20: =Poland!F20+Austria!F20+'Czech Republic'!F20+Greece!F20+Hungary!F20+Slovakia!F20+Croatia!F20 -> 322.31785 | G20: =Poland!G20+Austria!G20+'Czech Republic'!G20+Greece!G20+Hungary!G20+Slovakia!G20+Croatia!G20 -> 338.63737 | H20: =Poland!H20+Austria!H20+'Czech Republic'!H20+Greece!H20+Hungary!H20+Slovakia!H20+Croatia!H20 -> 345.76303 | I20: =Poland!I20+Austria!I20+'Czech Republic'!I20+Greece!I20+Hungary!I20+Slovakia!I20+Croatia!I20 -> 349.09182 | ... P20: =Poland!P20+Austria!P20+'Czech Republic'!P20+Greece!P20+Hungary!P20+Slovakia!P20+Croatia!P20 -> 378.64304 | R20: =(J20/D20)^(1/6)-1 -> 0.012659029 | S20: =(P20/J20)^(1/6)-1 -> 0.011967752
A21: Growth rate (%) | C21: =C20/B20-1 -> 0.031983414 | D21: =D20/C20-1 -> 0.021618153 | E21: =E20/D20-1 -> 0.019646351 | F21: =F20/E20-1 -> -0.033093959 | G21: =G20/F20-1 -> 0.050631769 | H21: =H20/G20-1 -> 0.021042145 | I21: =I20/H20-1 -> 0.009627378 | J21: =J20/I20-1 -> 0.0099276833 | ... P21: =P20/O20-1 -> 0.0088050583
A22: Large enterprises (250+ employees) | B22: =Poland!B22+Austria!B22+'Czech Republic'!B22+Greece!B22+Hungary!B22+Slovakia!B22+Croatia!B22 -> 9.7070413 | C22: =Poland!C22+Austria!C22+'Czech Republic'!C22+Greece!C22+Hungary!C22+Slovakia!C22+Croatia!C22 -> 10.05411 | D22: =Poland!D22+Austria!D22+'Czech Republic'!D22+Greece!D22+Hungary!D22+Slovakia!D22+Croatia!D22 -> 10.386775 | E22: =Poland!E22+Austria!E22+'Czech Republic'!E22+Greece!E22+Hungary!E22+Slovakia!E22+Croatia!E22 -> 10.464251 | F22: =Poland!F22+Austria!F22+'Czech Republic'!F22+Greece!F22+Hungary!F22+Slovakia!F22+Croatia!F22 -> 10.137901 | G22: =Poland!G22+Austria!G22+'Czech Republic'!G22+Greece!G22+Hungary!G22+Slovakia!G22+Croatia!G22 -> 10.43184 | H22: =Poland!H22+Austria!H22+'Czech Republic'!H22+Greece!H22+Hungary!H22+Slovakia!H22+Croatia!H22 -> 10.690449 | I22: =Poland!I22+Austria!I22+'Czech Republic'!I22+Greece!I22+Hungary!I22+Slovakia!I22+Croatia!I22 -> 10.720171 | ... P22: =Poland!P22+Austria!P22+'Czech Republic'!P22+Greece!P22+Hungary!P22+Slovakia!P22+Croatia!P22 -> 11.637745 | R22: =(J22/D22)^(1/6)-1 -> 0.0074795473 | S22: =(P22/J22)^(1/6)-1 -> 0.011568068
A23: Growth rate (%) | C23: =C22/B22-1 -> 0.035754301 | D23: =D22/C22-1 -> 0.033087528 | E23: =E22/D22-1 -> 0.0074590316 | F23: =F22/E22-1 -> -0.031187095 | G23: =G22/F22-1 -> 0.028994079 | H23: =H22/G22-1 -> 0.024790296 | I23: =I22/H22-1 -> 0.0027802645 | J23: =J22/I22-1 -> 0.013202989 | ... P23: =P22/O22-1 -> 0.0080935043
A24: Number of all enterprises | B24: =B18+B20+B22 -> 4158.3979 | C24: =C18+C20+C22 -> 4160.9546 | D24: =D18+D20+D22 -> 4215.7803 | E24: =E18+E20+E22 -> 4360.5797 | F24: =F18+F20+F22 -> 4401.9176 | G24: =G18+G20+G22 -> 4655.5465 | H24: =H18+H20+H22 -> 4854.201 | I24: =I18+I20+I22 -> 4881.0568 | ... P24: =P18+P20+P22 -> 5310.4509 | R24: =(J24/D24)^(1/6)-1 -> 0.025979818 | S24: =(P24/J24)^(1/6)-1 -> 0.0129082
A25: Growth rate (%) | C25: =C24/B24-1 -> 0.00061482392 | D25: =D24/C24-1 -> 0.013176229 | E25: =E24/D24-1 -> 0.034346997 | F25: =F24/E24-1 -> 0.009479916 | G25: =G24/F24-1 -> 0.05761783 | H25: =H24/G24-1 -> 0.042670482 | I25: =I24/H24-1 -> 0.0055324952 | J25: =J24/I24-1 -> 0.0073885584 | ... P25: =P24/O24-1 -> 0.011401288
A27: Percentage of enterprises using cloud computing
A28: Percent of microenterprises using cloud computing | B28: =B34/B18 -> 0.069345581 | C28: =C34/C18 -> 0.080986551 | D28: =D34/D18 -> 0.094503563 | E28: =E34/E18 -> 0.11065462 | F28: =F34/F18 -> 0.12932043 | G28: =G34/G18 -> 0.15169014 | H28: =H34/H18 -> 0.17747194 | I28: =I34/I18 -> 0.20707046 | ... P28: =P34/P18 -> 0.4752687
A29: Percent of SME using cloud computing | B29: =B36/B20 -> 0.11488284 | C29: =C36/C20 -> 0.14059932 | D29: =D36/D20 -> 0.1716105 | E29: =E36/E20 -> 0.20958246 | F29: =F36/F20 -> 0.25564668 | G29: =G36/G20 -> 0.30822647 | H29: =H36/H20 -> 0.36628783 | I29: =I36/I20 -> 0.42772883 | ... P29: =P36/P20 -> 0.78252853
A30: Percent of large enterprises using cloud computing | B30: =B38/B22 -> 0.28914034 | C30: =C38/C22 -> 0.36528339 | D30: =D38/D22 -> 0.44965655 | E30: =E38/E22 -> 0.53705933 | F30: =F38/F22 -> 0.62258108 | G30: =G38/G22 -> 0.69883238 | H30: =H38/H22 -> 0.7637952 | I30: =I38/I22 -> 0.81625577 | ... P30: =P38/P22 -> 0.96813844
A31: Percent of all enterprises using cloud computing | B31: =B40/B24 -> 0.073254359 | C31: =C40/C24 -> 0.086258168 | D31: =D40/D24 -> 0.1013581 | E31: =E40/E24 -> 0.11924054 | F31: =F40/F24 -> 0.13970632 | G31: =G40/G24 -> 0.16430235 | H31: =H40/H24 -> 0.19221249 | I31: =I40/I24 -> 0.22418983 | ... P31: =P40/P24 -> 0.49825689
A33: Number of enterprises using cloud computing (thousands)
A34: Number of microenterprises using cloud computing | B34: =Poland!B34+Austria!B34+'Czech Republic'!B34+Greece!B34+Hungary!B34+Slovakia!B34+Croatia!B34 -> 266.18994 | C34: =Poland!C34+Austria!C34+'Czech Republic'!C34+Greece!C34+Hungary!C34+Slovakia!C34+Croatia!C34 -> 310.2507 | D34: =Poland!D34+Austria!D34+'Czech Republic'!D34+Greece!D34+Hungary!D34+Slovakia!D34+Croatia!D34 -> 366.52892 | E34: =Poland!E34+Austria!E34+'Czech Republic'!E34+Greece!E34+Hungary!E34+Slovakia!E34+Croatia!E34 -> 444.4737 | F34: =Poland!F34+Austria!F34+'Czech Republic'!F34+Greece!F34+Hungary!F34+Slovakia!F34+Croatia!F34 -> 526.26456 | G34: =Poland!G34+Austria!G34+'Czech Republic'!G34+Greece!G34+Hungary!G34+Slovakia!G34+Croatia!G34 -> 653.25014 | H34: =Poland!H34+Austria!H34+'Czech Republic'!H34+Greece!H34+Hungary!H34+Slovakia!H34+Croatia!H34 -> 798.22396 | I34: =Poland!I34+Austria!I34+'Czech Republic'!I34+Greece!I34+Hungary!I34+Slovakia!I34+Croatia!I34 -> 936.21625 | ... P34: =Poland!P34+Austria!P34+'Czech Republic'!P34+Greece!P34+Hungary!P34+Slovakia!P34+Croatia!P34 -> 2338.4028 | R34: =(J34/D34)^(1/6)-1 -> 0.19980327 | S34: =(P34/J34)^(1/6)-1 -> 0.13507652
A35: Growth rate (%) | C35: =C34/B34-1 -> 0.16552378 | D35: =D34/C34-1 -> 0.18139595 | E35: =E34/D34-1 -> 0.21265655 | F35: =F34/E34-1 -> 0.18401732 | G35: =G34/F34-1 -> 0.2412961 | H35: =H34/G34-1 -> 0.22192696 | I35: =I34/H34-1 -> 0.17287415 | J35: =J34/I34-1 -> 0.16786412 | ... P35: =P34/O34-1 -> 0.10139376
A36: Number of SME using cloud computing | B36: =Poland!B36+Austria!B36+'Czech Republic'!B36+Greece!B36+Hungary!B36+Slovakia!B36+Croatia!B36 -> 35.624136 | C36: =Poland!C36+Austria!C36+'Czech Republic'!C36+Greece!C36+Hungary!C36+Slovakia!C36+Croatia!C36 -> 44.993018 | D36: =Poland!D36+Austria!D36+'Czech Republic'!D36+Greece!D36+Hungary!D36+Slovakia!D36+Croatia!D36 -> 56.104069 | E36: =Poland!E36+Austria!E36+'Czech Republic'!E36+Greece!E36+Hungary!E36+Slovakia!E36+Croatia!E36 -> 69.864252 | F36: =Poland!F36+Austria!F36+'Czech Republic'!F36+Greece!F36+Hungary!F36+Slovakia!F36+Croatia!F36 -> 82.399486 | G36: =Poland!G36+Austria!G36+'Czech Republic'!G36+Greece!G36+Hungary!G36+Slovakia!G36+Croatia!G36 -> 104.377 | H36: =Poland!H36+Austria!H36+'Czech Republic'!H36+Greece!H36+Hungary!H36+Slovakia!H36+Croatia!H36 -> 126.64879 | I36: =Poland!I36+Austria!I36+'Czech Republic'!I36+Greece!I36+Hungary!I36+Slovakia!I36+Croatia!I36 -> 149.31663 | ... P36: =Poland!P36+Austria!P36+'Czech Republic'!P36+Greece!P36+Hungary!P36+Slovakia!P36+Croatia!P36 -> 296.29898 | R36: =(J36/D36)^(1/6)-1 -> 0.20650805 | S36: =(P36/J36)^(1/6)-1 -> 0.093769333
A37: Growth rate (%) | C37: =C36/B36-1 -> 0.26299255 | D37: =D36/C36-1 -> 0.24695055 | E37: =E36/D36-1 -> 0.24526177 | F37: =F36/E36-1 -> 0.17942271 | G37: =G36/F36-1 -> 0.26671907 | H37: =H36/G36-1 -> 0.21337832 | I37: =I36/H36-1 -> 0.17898193 | J37: =J36/I36-1 -> 0.15895752 | ... P37: =P36/O36-1 -> 0.054589469
A38: Number of large enterprises using cloud computing | B38: =Poland!B38+Austria!B38+'Czech Republic'!B38+Greece!B38+Hungary!B38+Slovakia!B38+Croatia!B38 -> 2.8066973 | C38: =Poland!C38+Austria!C38+'Czech Republic'!C38+Greece!C38+Hungary!C38+Slovakia!C38+Croatia!C38 -> 3.6725994 | D38: =Poland!D38+Austria!D38+'Czech Republic'!D38+Greece!D38+Hungary!D38+Slovakia!D38+Croatia!D38 -> 4.6704816 | E38: =Poland!E38+Austria!E38+'Czech Republic'!E38+Greece!E38+Hungary!E38+Slovakia!E38+Croatia!E38 -> 5.6199235 | F38: =Poland!F38+Austria!F38+'Czech Republic'!F38+Greece!F38+Hungary!F38+Slovakia!F38+Croatia!F38 -> 6.3116654 | G38: =Poland!G38+Austria!G38+'Czech Republic'!G38+Greece!G38+Hungary!G38+Slovakia!G38+Croatia!G38 -> 7.2901078 | H38: =Poland!H38+Austria!H38+'Czech Republic'!H38+Greece!H38+Hungary!H38+Slovakia!H38+Croatia!H38 -> 8.1653134 | I38: =Poland!I38+Austria!I38+'Czech Republic'!I38+Greece!I38+Hungary!I38+Slovakia!I38+Croatia!I38 -> 8.7504014 | ... P38: =Poland!P38+Austria!P38+'Czech Republic'!P38+Greece!P38+Hungary!P38+Slovakia!P38+Croatia!P38 -> 11.266948 | R38: =(J38/D38)^(1/6)-1 -> 0.12214367 | S38: =(P38/J38)^(1/6)-1 -> 0.032029975
A39: Growth rate (%) | C39: =C38/B38-1 -> 0.30851283 | D39: =D38/C38-1 -> 0.27171008 | E39: =E38/D38-1 -> 0.20328564 | F39: =F38/E38-1 -> 0.12308744 | G39: =G38/F38-1 -> 0.15502127 | H39: =H38/G38-1 -> 0.12005386 | I39: =I38/H38-1 -> 0.071655303 | J39: =J38/I38-1 -> 0.06567423 | ... P39: =P38/O38-1 -> 0.016677752
A40: Number of all enterprises using cloud computing | B40: =B38+B36+B34 -> 304.62077 | C40: =C38+C36+C34 -> 358.91632 | D40: =D38+D36+D34 -> 427.30347 | E40: =E38+E36+E34 -> 519.95787 | F40: =F38+F36+F34 -> 614.97571 | G40: =G38+G36+G34 -> 764.91725 | H40: =H38+H36+H34 -> 933.03806 | I40: =I38+I36+I34 -> 1094.2833 | ... P40: =P38+P36+P34 -> 2645.9688 | R40: =(J40/D40)^(1/6)-1 -> 0.19997315 | S40: =(P40/J40)^(1/6)-1 -> 0.12928403
A41: Growth rate (%) | C41: =C40/B40-1 -> 0.17823981 | D41: =D40/C40-1 -> 0.19053788 | E41: =E40/D40-1 -> 0.21683512 | F41: =F40/E40-1 -> 0.1827414 | G41: =G40/F40-1 -> 0.24381701 | H41: =H40/G40-1 -> 0.21978955 | I41: =I40/H40-1 -> 0.17281741 | J41: =J40/I40-1 -> 0.16583164 | ... P41: =P40/O40-1 -> 0.095560211
A43: Total cloud computing market size (€ m) | B43: =B55+B111 -> 604.40326 | C43: =C55+C111 -> 766.58844 | D43: =D55+D111 -> 982.41971 | E43: =E55+E111 -> 1269.0813 | F43: =F55+F111 -> 1571.7157 | G43: =G55+G111 -> 1986.9813 | H43: =H55+H111 -> 2520.7643 | I43: =I55+I111 -> 3147.438 | ... P43: =P55+P111 -> 10331.793 | R43: =(J43/D43)^(1/6)-1 -> 0.2571425 | S43: =(P43/J43)^(1/6)-1 -> 0.17741237
A44: Growth rate (%) | C44: =C43/B43-1 -> 0.26833935 | D44: =D43/C43-1 -> 0.28154778 | E44: =E43/D43-1 -> 0.29179137 | F44: =F43/E43-1 -> 0.23846731 | G44: =G43/F43-1 -> 0.26421164 | H44: =H43/G43-1 -> 0.26864016 | I44: =I43/H43-1 -> 0.24860464 | J44: =J43/I43-1 -> 0.2321028 | ... P44: =P43/O43-1 -> 0.14426293
A46: Public cloud (by size of enterprises) (€ m)
A47: Microenterprises (0-9 employees) | B47: =Poland!B47+Austria!B47+'Czech Republic'!B47+Greece!B47+Hungary!B47+Slovakia!B47+Croatia!B47 -> 25.879968 | C47: =Poland!C47+Austria!C47+'Czech Republic'!C47+Greece!C47+Hungary!C47+Slovakia!C47+Croatia!C47 -> 34.085921 | D47: =Poland!D47+Austria!D47+'Czech Republic'!D47+Greece!D47+Hungary!D47+Slovakia!D47+Croatia!D47 -> 46.673206 | E47: =Poland!E47+Austria!E47+'Czech Republic'!E47+Greece!E47+Hungary!E47+Slovakia!E47+Croatia!E47 -> 62.866763 | F47: =Poland!F47+Austria!F47+'Czech Republic'!F47+Greece!F47+Hungary!F47+Slovakia!F47+Croatia!F47 -> 84.479821 | G47: =Poland!G47+Austria!G47+'Czech Republic'!G47+Greece!G47+Hungary!G47+Slovakia!G47+Croatia!G47 -> 113.68498 | H47: =Poland!H47+Austria!H47+'Czech Republic'!H47+Greece!H47+Hungary!H47+Slovakia!H47+Croatia!H47 -> 155.24631 | I47: =Poland!I47+Austria!I47+'Czech Republic'!I47+Greece!I47+Hungary!I47+Slovakia!I47+Croatia!I47 -> 202.1687 | ... P47: =Poland!P47+Austria!P47+'Czech Republic'!P47+Greece!P47+Hungary!P47+Slovakia!P47+Croatia!P47 -> 921.32627 | R47: =(J47/D47)^(1/6)-1 -> 0.33144533 | S47: =(P47/J47)^(1/6)-1 -> 0.23471757
...

Sheet Poland
A1: Year | B1: 2016 | C1: 2017 | D1: 2018 | E1: 2019 | F1: 2020 | G1: 2021 | H1: 2022 | I1: 2023 | J1: 2024 | K1: 2025e | L1: 2026f | M1: 2027f | N1: 2028f | O1: 2029f | P1: 2030f | R1: CAGR 2019-2024 | S1: CAGR 2025-2030
A2: Total IT market size (€ m) | B2: =B4+B6+B8 -> 9299.5443 | C2: =C4+C6+C8 -> 9981.5665 | D2: =D4+D6+D8 -> 10760.683 | E2: =E4+E6+E8 -> 11431.027 | F2: =F4+F6+F8 -> 11596.75 | G2: =G4+G6+G8 -> 13106.045 | H2: =H4+H6+H8 -> 14005.695 | I2: =I4+I6+I8 -> 15104.365 | ... P2: =P4+P6+P8 -> 24173.034 | R2: =(J2/D2)^(1/6)-1 -> 0.079094117 | S2: =(P2/J2)^(1/6)-1 -> 0.06052904
A3: Growth rate (%) | C3: =C2/B2-1 -> 0.073339313 | D3: =D2/C2-1 -> 0.078055502 | E3: =E2/D2-1 -> 0.06229573 | F3: =F2/E2-1 -> 0.014497591 | G3: =G2/F2-1 -> 0.13014815 | H3: =H2/G2-1 -> 0.068643857 | I3: =I2/H2-1 -> 0.078444524 | J3: =J2/I2-1 -> 0.12484663 | ... P3: =P2/O2-1 -> 0.047895339
A4: Software | B4: 1615.0109 | C4: 1735.2955 | D4: 1836.4424 | E4: 1935.2326 | F4: 1984.855 | G4: 2061.9576 | H4: 2184.3829 | I4: 2468.5777 | J4: 2793.5177 | K4: 3059.759 | L4: 3316.0726 | M4: 3515.321 | N4: 3744.933 | O4: 3983.355 | P4: 4223.0619 | R4: =(J4/D4)^(1/6)-1 -> 0.072413692 | S4: =(P4/J4)^(1/6)-1 -> 0.071303863
A5: Growth rate (%) | C5: =C4/B4-1 -> 0.074479107 | D5: =D4/C4-1 -> 0.05828801 | E5: =E4/D4-1 -> 0.053794332 | F5: =F4/E4-1 -> 0.025641567 | G5: =G4/F4-1 -> 0.038845463 | H5: =H4/G4-1 -> 0.059373294 | I5: =I4/H4-1 -> 0.13010303 | J5: =J4/I4-1 -> 0.13163045 | ... P5: =P4/O4-1 -> 0.060177131
A6: Hardware | B6: 4613.2157 | C6: 5023.8411 | D6: 5551.5202 | E6: 5930.3369 | F6: 6034.5517 | G6: 7324.7373 | H6: 7655.2593 | I6: 7876.4597 | J6: 8788.142 | K6: 9453.3222 | L6: 9974.3679 | M6: 10338.013 | N6: 10680.834 | O6: 10999.15 | P6: 11289.958 | R6: =(J6/D6)^(1/6)-1 -> 0.079561836 | S6: =(P6/J6)^(1/6)-1 -> 0.042635585
A7: Growth rate (%) | C7: =C6/B6-1 -> 0.08901066 | D7: =D6/C6-1 -> 0.105035 | E7: =E6/D6-1 -> 0.068236567 | F7: =F6/E6-1 -> 0.017573168 | G7: =G6/F6-1 -> 0.21379974 | H7: =H6/G6-1 -> 0.045124083 | I7: =I6/H6-1 -> 0.028895211 | J7: =J6/I6-1 -> 0.11574773 | ... P7: =P6/O6-1 -> 0.026439124
A8: Services | B8: 3071.3176 | C8: 3222.4299 | D8: 3372.72 | E8: 3565.4577 | F8: 3577.3428 | G8: 3719.3501 | H8: 4166.0524 | I8: 4759.3272 | J8: 5408.4339 | K8: 5980.7669 | L8: 6517.1645 | M8: 6982.5556 | N8: 7515.4869 | O8: 8085.6707 | P8: 8660.0141 | R8: =(J8/D8)^(1/6)-1 -> 0.081886929 | S8: =(P8/J8)^(1/6)-1 -> 0.081619508
A9: Growth rate (%) | C9: =C8/B8-1 -> 0.049201112 | D9: =D8/C8-1 -> 0.046638747 | E9: =E8/D8-1 -> 0.057146074 | F9: =F8/E8-1 -> 0.0033334168 | G9: =G8/F8-1 -> 0.039696311 | H9: =H8/G8-1 -> 0.12010222 | I9: =I8/H8-1 -> 0.14240697 | J9: =J8/I8-1 -> 0.13638622 | ... P9: =P8/O8-1 -> 0.071032244
A11: Smartphones market size (€ m) | B11: 1873.6856 | C11: 2216.8136 | D11: 2573.1413 | E11: 2707.7522 | F11: 2319.8336 | G11: 3181.3587 | H11: 3148.4867 | I11: 3212.213 | J11: 3512.037 | K11: 3731.3699 | L11: 3900.0517 | M11: 4000.0416 | N11: 4085.0589 | O11: 4158.5832 | P11: 4219.8889 | R11: =(J11/D11)^(1/6)-1 -> 0.053212267 | S11: =(P11/J11)^(1/6)-1 -> 0.031075156
A12: Growth rate (%) | C12: =C11/B11-1 -> 0.18312999 | D12: =D11/C11-1 -> 0.16073865 | E12: =E11/D11-1 -> 0.052313853 | F12: =F11/E11-1 -> -0.14326224 | G12: =G11/F11-1 -> 0.37137368 | H12: =H11/G11-1 -> -0.010332688 | I12: =I11/H11-1 -> 0.020240299 | J12: =J11/I11-1 -> 0.093338759 | ... P12: =P11/O11-1 -> 0.014741964
A14: Cybersecurity market size (€ m) | B14: 253.95765 | C14: 284.89601 | D14: 327.05276 | E14: 360.93874 | F14: 370.35188 | G14: 402.23624 | H14: 475.00383 | I14: 542.01077 | J14: 627.45755 | K14: 791.42892 | L14: 956.75508 | M14: 963.34559 | N14: 976.29511 | O14: 1040.3916 | P14: 1144.4307 | R14: =(J14/D14)^(1/6)-1 -> 0.11470793 | S14: =(P14/J14)^(1/6)-1 -> 0.10535266
A15: Growth rate (%) | C15: =C14/B14-1 -> 0.1218249 | D15: =D14/C14-1 -> 0.1479724 | E15: =E14/D14-1 -> 0.10361013 | F15: =F14/E14-1 -> 0.026079609 | G15: =G14/F14-1 -> 0.086092069 | H15: =H14/G14-1 -> 0.18090761 | I15: =I14/H14-1 -> 0.14106609 | J15: =J14/I14-1 -> 0.15764777 | ... P15: =P14/O14-1 -> 0.1
A17: Enterprises (by size) (number of enterprises in thousands)
A18: Microenterprises (0-9 employees) | B18: 726.01385 | C18: 743.81869 | D18: 745.12372 | E18: 754.48772 | F18: 768.18886 | G18: 780.17634 | H18: 852.96648 | I18: 873.93681 | J18: 869.01861 | K18: 876.49216 | L18: 885.99723 | M18: 895.37264 | N18: 903.00275 | O18: 912.42158 | P18: 920.39335 | R18: =(J18/D18)^(1/6)-1 -> 0.025967132 | S18: =(P18/J18)^(1/6)-1 -> 0.0096187316
A19: Growth rate (%) | C19: =C18/B18-1 -> 0.024524111 | D19: =D18/C18-1 -> 0.0017544952 | E19: =E18/D18-1 -> 0.012567037 | F19: =F18/E18-1 -> 0.018159527 | G19: =G18/F18-1 -> 0.015604857 | H19: =H18/G18-1 -> 0.09329961 | I19: =I18/H18-1 -> 0.024585174 | J19: =J18/I18-1 -> -0.0056276423 | ... P19: =P18/O18-1 -> 0.0087369419
A20: SME (10-249 employees) | B20: 140.52218 | C20: 145.54094 | D20: 150.46679 | E20: 151.81671 | F20: 150.68485 | G20: 156.5012 | H20: 154.56408 | I20: 154.96105 | J20: 155.78067 | K20: 157.84591 | L20: 159.87826 | M20: 161.91875 | N20: 163.48488 | O20: 165.0677 | P20: 166.14508 | R20: =(J20/D20)^(1/6)-1 -> 0.0058012051 | S20: =(P20/J20)^(1/6)-1 -> 0.010793223
A21: Growth rate (%) | C21: =C20/B20-1 -> 0.035715077 | D21: =D20/C20-1 -> 0.033845108 | E21: =E20/D20-1 -> 0.0089715382 | F21: =F20/E20-1 -> -0.0074554485 | G21: =G20/F20-1 -> 0.038599476 | H21: =H20/G20-1 -> -0.012377675 | I21: =I20/H20-1 -> 0.0025683163 | J21: =J20/I20-1 -> 0.0052891874 | ... P21: =P20/O20-1 -> 0.0065268973
A22: Large enterprises (250+ employees) | B22: 4.6965969 | C22: 4.8727765 | D22: 5.0567755 | E22: 5.1072507 | F22: 4.9719012 | G22: 5.1352403 | H22: 5.2112487 | I22: 5.1343709 | J22: 5.2249167 | K22: 5.3311406 | L22: 5.41576 | M22: 5.4901257 | N22: 5.559907 | O22: 5.6221213 | P22: 5.6703803 | R22: =(J22/D22)^(1/6)-1 -> 0.0054665255 | S22: =(P22/J22)^(1/6)-1 -> 0.013729621
A23: Growth rate (%) | C23: =C22/B22-1 -> 0.03751218 | D23: =D22/C22-1 -> 0.037760602 | E23: =E22/D22-1 -> 0.0099817139 | F23: =F22/E22-1 -> -0.026501457 | G23: =G22/F22-1 -> 0.032852444 | H23: =H22/G22-1 -> 0.014801334 | I23: =I22/H22-1 -> -0.014752266 | J23: =J22/I22-1 -> 0.017635212 | ... P23: =P22/O22-1 -> 0.0085837792
A24: Number of all enterprises | B24: =B18+B20+B22 -> 871.23263 | C24: =C18+C20+C22 -> 894.23241 | D24: =D18+D20+D22 -> 900.64729 | E24: =E18+E20+E22 -> 911.41168 | F24: =F18+F20+F22 -> 923.84561 | G24: =G18+G20+G22 -> 941.81278 | H24: =H18+H20+H22 -> 1012.7418 | I24: =I18+I20+I22 -> 1034.0322 | ... P24: =P18+P20+P22 -> 1092.2088 | R24: =(J24/D24)^(1/6)-1 -> 0.022622743 | S24: =(P24/J24)^(1/6)-1 -> 0.009817847
A25: Growth rate (%) | C25: =C24/B24-1 -> 0.026399131 | D25: =D24/C24-1 -> 0.0071736095 | E25: =E24/D24-1 -> 0.011951839 | F25: =F24/E24-1 -> 0.013642495 | G25: =G24/F24-1 -> 0.019448242 | H25: =H24/G24-1 -> 0.075311184 | I25: =I24/H24-1 -> 0.021022556 | J25: =J24/I24-1 -> -0.0038761268 | ... P25: =P24/O24-1 -> 0.008399333
A27: Percentage of enterprises using cloud computing
A28: Percent of microenterprises using cloud computing | B28: 0.032269528 | C28: 0.045014604 | D28: 0.062468499 | E28: 0.086079932 | F28: 0.11749738 | G28: 0.15839424 | H28: 0.2101364 | I28: 0.27329233 | J28: 0.34708865 | K28: 0.42904711 | L28: 0.5150907 | M28: 0.6002489 | N28: 0.67975006 | O28: 0.7500248 | P28: 0.809207
A29: Percent of SME using cloud computing | B29: 0.06662654 | C29: 0.09290258 | D29: 0.12811888 | E29: 0.17412205 | F29: 0.23224345 | G29: 0.30265588 | H29: 0.38374595 | I29: 0.47186112 | J29: 0.56176526 | K29: 0.64778872 | L29: 0.72518673 | M29: 0.79106242 | N29: 0.84453234 | O29: 0.8862856 | P29: 0.91791528
A30: Percent of large enterprises using cloud computing | B30: 0.26270054 | C30: 0.34893304 | D30: 0.4463361 | E30: 0.54804167 | F30: 0.64588694 | G30: 0.73287435 | H30: 0.80494651 | I30: 0.86125452 | J30: 0.90326108 | K30: 0.93353126 | L30: 0.95480366 | M30: 0.96949062 | N30: 0.97950735 | O30: 0.98628196 | P30: 0.99083791
A31: Percent of all enterprises using cloud computing | B31: 0.039053209 | C31: 0.054464706 | D31: 0.075591655 | E31: 0.10333407 | F31: 0.13905682 | G31: 0.18549858 | H31: 0.2396933 | I31: 0.3059695 | J31: 0.38237755 | K31: 0.46484402 | L31: 0.54930688 | M31: 0.63122748 | N31: 0.70643361 | O31: 0.77201748 | P31: 0.8266865
A33: Number of enterprises using cloud computing (thousands)
A34: Number of microenterprises using cloud computing | B34: =B28*B18 -> 23.428124 | C34: =C28*C18 -> 33.482704 | D34: =D28*D18 -> 46.54676 | E34: =E28*E18 -> 64.946251 | F34: =F28*F18 -> 90.260182 | G34: =G28*G18 -> 123.57544 | H34: =H28*H18 -> 179.23931 | I34: =I28*I18 -> 238.84023 | ... P34: =P28*P18 -> 744.78875 | R34: =(J34/D34)^(1/6)-1 -> 0.36541082 | S34: =(P34/J34)^(1/6)-1 -> 0.16259184
A35: Growth rate (%) | C35: =C34/B34-1 -> 0.42916706 | D35: =D34/C34-1 -> 0.39017328 | E35: =E34/D34-1 -> 0.39529048 | F35: =F34/E34-1 -> 0.38976739 | G35: =G34/F34-1 -> 0.3691025 | H35: =H34/G34-1 -> 0.45044443 | I35: =I34/H34-1 -> 0.33252146 | J35: =J34/I34-1 -> 0.2628798 | ... P35: =P34/O34-1 -> 0.088333341
A36: Number of SME using cloud computing | B36: =B29*B20 -> 9.3625066 | C36: =C29*C20 -> 13.521129 | D36: =D29*D20 -> 19.277637 | E36: =E29*E20 -> 26.434637 | F36: =F29*F20 -> 34.995569 | G36: =G29*G20 -> 47.36601 | H36: =H29*H20 -> 59.31334 | I36: =I29*I20 -> 73.120094 | ... P36: =P29*P20 -> 152.50711 | R36: =(J36/D36)^(1/6)-1 -> 0.28677448 | S36: =(P36/J36)^(1/6)-1 -> 0.096992373
A37: Growth rate (%) | C37: =C36/B36-1 -> 0.4441783 | D37: =D36/C36-1 -> 0.42574169 | E37: =E36/D36-1 -> 0.37125918 | F37: =F36/E36-1 -> 0.32385282 | G37: =G36/F36-1 -> 0.35348593 | H37: =H36/G36-1 -> 0.25223425 | I37: =I36/H36-1 -> 0.23277655 | J37: =J36/I36-1 -> 0.19682789 | ... P37: =P36/O36-1 -> 0.042447733
A38: Number of large enterprises using cloud computing | B38: =B30*B22 -> 1.2337986 | C38: =C30*C22 -> 1.7002727 | D38: =D30*D22 -> 2.2570214 | E38: =E30*E22 -> 2.7989862 | F38: =F30*F22 -> 3.211286 | G38: =G30*G22 -> 3.7634859 | H38: =H30*H22 -> 4.1947764 | I38: =I30*I22 -> 4.4220002 | ... P38: =P30*P22 -> 5.6184278 | R38: =(J38/D38)^(1/6)-1 -> 0.1308183 | S38: =(P38/J38)^(1/6)-1 -> 0.02948579
A39: Growth rate (%) | C39: =C38/B38-1 -> 0.37807966 | D39: =D38/C38-1 -> 0.32744673 | E39: =E38/D38-1 -> 0.24012389 | F39: =F38/E38-1 -> 0.14730326 | G39: =G38/F38-1 -> 0.17195599 | H39: =H38/G38-1 -> 0.1145987 | I39: =I38/H38-1 -> 0.054168262 | J39: =J38/I38-1 -> 0.06726903 | ... P39: =P38/O38-1 -> 0.013242757
A40: Number of all enterprises using cloud computing | B40: =B38+B36+B34 -> 34.02443 | C40: =C38+C36+C34 -> 48.704105 | D40: =D38+D36+D34 -> 68.081419 | E40: =E38+E36+E34 -> 94.179874 | F40: =F38+F36+F34 -> 128.46704 | G40: =G38+G36+G34 -> 174.70494 | H40: =H38+H36+H34 -> 242.74743 | I40: =I38+I36+I34 -> 316.38232 | ... P40: =P38+P36+P34 -> 902.91428 | R40: =(J40/D40)^(1/6)-1 -> 0.3398367 | S40: =(P40/J40)^(1/6)-1 -> 0.14828877
A41: Growth rate (%) | C41: =C40/B40-1 -> 0.43144517 | D41: =D40/C40-1 -> 0.39785791 | E41: =E40/D40-1 -> 0.38334183 | F41: =F40/E40-1 -> 0.36406039 | G41: =G40/F40-1 -> 0.35992034 | H41: =H40/G40-1 -> 0.3894709 | I41: =I40/H40-1 -> 0.30333955 | J41: =J40/I40-1 -> 0.24488033 | ... P41: =P40/O40-1 -> 0.079807304
A43: Total cloud computing market size (€ m) | B43: =B55+B111 -> 139.4767 | C43: =C55+C111 -> 182.93872 | D43: =D55+D111 -> 239.48228 | E43: =E55+E111 -> 312.28116 | F43: =F55+F111 -> 385.49673 | G43: =G55+G111 -> 492.47464 | H43: =H55+H111 -> 621.43933 | I43: =I55+I111 -> 826.81692 | ... P43: =P55+P111 -> 3245.6834 | R43: =(J43/D43)^(1/6)-1 -> 0.28608436 | S43: =(P43/J43)^(1/6)-1 -> 0.20061197
A44: Growth rate (%) | C44: =C43/B43-1 -> 0.31160778 | D44: =D43/C43-1 -> 0.30908469 | E44: =E43/D43-1 -> 0.30398437 | F44: =F43/E43-1 -> 0.23445403 | G44: =G43/F43-1 -> 0.27750667 | H44: =H43/G43-1 -> 0.2618707 | I44: =I43/H43-1 -> 0.33048697 | J44: =J43/I43-1 -> 0.31063203 | ... P44: =P43/O43-1 -> 0.14955977
A46: Public cloud (by size of enterprises) (€ m)
A47: Microenterprises (0-9 employees) | B47: 5.5532851 | C47: 7.5330778 | D47: 10.467136 | E47: 14.656433 | F47: 20.061965 | G47: 28.087663 | H47: 39.028122 | I47: 54.942037 | J47: 77.372036 | K47: 105.18362 | L47: 138.73444 | M47: 173.90898 | N47: 213.06599 | O47: 261.51338 | P47: 311.31858 | R47: =(J47/D47)^(1/6)-1 -> 0.39570198 | S47: =(P47/J47)^(1/6)-1 -> 0.26115995
...

Sheet Austria
A1: Year | B1: 2016 | C1: 2017 | D1: 2018 | E1: 2019 | F1: 2020 | G1: 2021 | H1: 2022 | I1: 2023 | J1: 2024 | K1: 2025e | L1: 2026f | M1: 2027f | N1: 2028f | O1: 2029f | P1: 2030f | R1: CAGR 2019-2024 | S1: CAGR 2025-2030
A2: Total IT market size (€ m) | B2: =B4+B6+B8 -> 8368.9756 | C2: =C4+C6+C8 -> 8630.2134 | D2: =D4+D6+D8 -> 8986.2049 | E2: =E4+E6+E8 -> 9498.9866 | F2: =F4+F6+F8 -> 9832.2746 | G2: =G4+G6+G8 -> 10524.045 | H2: =H4+H6+H8 -> 11274.648 | I2: =I4+I6+I8 -> 12127.578 | ... P2: =P4+P6+P8 -> 18970.184 | R2: =(J2/D2)^(1/6)-1 -> 0.068402149 | S2: =(P2/J2)^(1/6)-1 -> 0.060102322
A3: Growth rate (%) | C3: =C2/B2-1 -> 0.031215027 | D3: =D2/C2-1 -> 0.04124944 | E3: =E2/D2-1 -> 0.057063212 | F3: =F2/E2-1 -> 0.035086697 | G3: =G2/F2-1 -> 0.070357078 | H3: =H2/G2-1 -> 0.071322709 | I3: =I2/H2-1 -> 0.075650242 | J3: =J2/I2-1 -> 0.102074 | ... P3: =P2/O2-1 -> 0.061319738
A4: Software | B4: 1662.9582 | C4: 1717.4788 | D4: 1800.1739 | E4: 1937.517 | F4: 2073.4693 | G4: 2211.7819 | H4: 2405.1331 | I4: 2628.633 | J4: 2950.5118 | K4: 3153.5526 | L4: 3379.7323 | M4: 3598.2954 | N4: 3848.6725 | O4: 4123.2591 | P4: 4419.714 | R4: =(J4/D4)^(1/6)-1 -> 0.08583495 | S4: =(P4/J4)^(1/6)-1 -> 0.069669149
A5: Growth rate (%) | C5: =C4/B4-1 -> 0.032785325 | D5: =D4/C4-1 -> 0.048149087 | E5: =E4/D4-1 -> 0.07629439 | F5: =F4/E4-1 -> 0.070168295 | G5: =G4/F4-1 -> 0.066705875 | H5: =H4/G4-1 -> 0.087418774 | I5: =I4/H4-1 -> 0.092926202 | J5: =J4/I4-1 -> 0.122451 | ... P5: =P4/O4-1 -> 0.071898199
A6: Hardware | B6: 2440.5791 | C6: 2529.0914 | D6: 2669.0222 | E6: 2834.7458 | F6: 2845.5733 | G6: 3107.097 | H6: 3341.4065 | I6: 3555.6523 | J6: 3874.037 | K6: 4047.8903 | L6: 4225.7339 | M6: 4388.1225 | N6: 4550.5811 | O6: 4711.3948 | P6: 4866.5709 | R6: =(J6/D6)^(1/6)-1 -> 0.064066073 | S6: =(P6/J6)^(1/6)-1 -> 0.038747234
A7: Growth rate (%) | C7: =C6/B6-1 -> 0.036266915 | D7: =D6/C6-1 -> 0.055328517 | E7: =E6/D6-1 -> 0.062091496 | F7: =F6/E6-1 -> 0.0038195704 | G7: =G6/F6-1 -> 0.091905439 | H7: =H6/G6-1 -> 0.075411068 | I7: =I6/H6-1 -> 0.064118456 | J7: =J6/I6-1 -> 0.089543263 | ... P7: =P6/O6-1 -> 0.032936326
A8: Services | B8: 4265.4383 | C8: 4383.6432 | D8: 4517.0087 | E8: 4726.7237 | F8: 4913.232 | G8: 5205.1658 | H8: 5528.1085 | I8: 5943.2926 | J8: 6540.9395 | K8: 6934.3854 | L8: 7396.5789 | M8: 7888.4795 | N8: 8439.8015 | O8: 9039.4922 | P8: 9683.8992 | R8: =(J8/D8)^(1/6)-1 -> 0.063648668 | S8: =(P8/J8)^(1/6)-1 -> 0.067583093
A9: Growth rate (%) | C9: =C8/B8-1 -> 0.027712251 | D9: =D8/C8-1 -> 0.030423451 | E9: =E8/D8-1 -> 0.04642784 | F9: =F8/E8-1 -> 0.039458257 | G9: =G8/F8-1 -> 0.059417887 | H9: =H8/G8-1 -> 0.062042713 | I9: =I8/H8-1 -> 0.075104196 | J9: =J8/I8-1 -> 0.10055822 | ... P9: =P8/O8-1 -> 0.071287966
A11: Smartphones market size (€ m) | B11: 357.45165 | C11: 357.604 | D11: 364.66455 | E11: 423.86621 | F11: 384.2223 | G11: 441.18317 | H11: 476.93773 | I11: 494.51609 | J11: 521.13991 | K11: 538.35181 | L11: 557.0896 | M11: 569.69614 | N11: 589.35989 | O11: 610.84604 | P11: 630.99353 | R11: =(J11/D11)^(1/6)-1 -> 0.061312951 | S11: =(P11/J11)^(1/6)-1 -> 0.032393106
A12: Growth rate (%) | C12: =C11/B11-1 -> 0.00042622716 | D12: =D11/C11-1 -> 0.01974404 | E12: =E11/D11-1 -> 0.16234553 | F12: =F11/E11-1 -> -0.093529285 | G12: =G11/F11-1 -> 0.14824976 | H12: =H11/G11-1 -> 0.081042431 | I12: =I11/H11-1 -> 0.036856721 | J12: =J11/I11-1 -> 0.053838126 | ... P12: =P11/O11-1 -> 0.032982916
A14: Cybersecurity market size (€ m) | B14: 232.75924 | C14: 248.63926 | D14: 275.65596 | E14: 296.51917 | F14: 292.90644 | G14: 312.74389 | H14: 356.86804 | I14: 390.10576 | J14: 426.21773 | K14: 460.35591 | L14: 501.10123 | M14: 539.77664 | N14: 575.4165 | O14: 612.43127 | P14: 656.22253 | R14: =(J14/D14)^(1/6)-1 -> 0.075335591 | S14: =(P14/J14)^(1/6)-1 -> 0.074574681
A15: Growth rate (%) | C15: =C14/B14-1 -> 0.068225083 | D15: =D14/C14-1 -> 0.10865823 | E15: =E14/D14-1 -> 0.075685669 | F15: =F14/E14-1 -> -0.012183799 | G15: =G14/F14-1 -> 0.06772623 | H15: =H14/G14-1 -> 0.14108718 | I15: =I14/H14-1 -> 0.093137281 | J15: =J14/I14-1 -> 0.092569695 | ... P15: =P14/O14-1 -> 0.071503961
A17: Enterprises (by size) (number of enterprises in thousands)
A18: Microenterprises (0-9 employees) | B18: 281.806 | C18: 289.874 | D18: 274.768 | E18: 288.827 | F18: 290.791 | G18: 362.34 | H18: 363.389 | I18: 364.029 | J18: 366.76515 | K18: 370.13611 | L18: 375.6291 | M18: 381.82012 | N18: 387.89707 | O18: 393.35244 | P18: 397.5212 | R18: =(J18/D18)^(1/6)-1 -> 0.049309614 | S18: =(P18/J18)^(1/6)-1 -> 0.013511556
A19: Growth rate (%) | C19: =C18/B18-1 -> 0.028629625 | D19: =D18/C18-1 -> -0.052112297 | E19: =E18/D18-1 -> 0.051166803 | F19: =F18/E18-1 -> 0.0067999183 | G19: =G18/F18-1 -> 0.24604957 | H19: =H18/G18-1 -> 0.0028950709 | I19: =I18/H18-1 -> 0.0017611981 | J19: =J18/I18-1 -> 0.0075163044 | ... P19: =P18/O18-1 -> 0.010598019
A20: SME (10-249 employees) | B20: 41.016 | C20: 41.754 | D20: 40.61 | E20: 41.11 | F20: 38.633 | G20: 40.821 | H20: 43.064 | I20: 42.944 | J20: 42.79749 | K20: 42.380304 | L20: 42.313408 | M20: 42.441167 | N20: 42.631269 | O20: 42.823707 | P20: 42.832461 | R20: =(J20/D20)^(1/6)-1 -> 0.0087825285 | S20: =(P20/J20)^(1/6)-1 -> 0.00013613969
A21: Growth rate (%) | C21: =C20/B20-1 -> 0.017992978 | D21: =D20/C20-1 -> -0.027398573 | E21: =E20/D20-1 -> 0.012312238 | F21: =F20/E20-1 -> -0.06025298 | G21: =G20/F20-1 -> 0.056635519 | H21: =H20/G20-1 -> 0.054947209 | I21: =I20/H20-1 -> -0.0027865503 | J21: =J20/I20-1 -> -0.0034116479 | ... P21: =P20/O20-1 -> 0.0002044233
A22: Large enterprises (250+ employees) | B22: 1.09 | C22: 1.127 | D22: 1.184 | E22: 1.208 | F22: 1.201 | G22: 1.209 | H22: 1.256 | I22: 1.301 | J22: 1.3149422 | K22: 1.3276126 | L22: 1.3456243 | M22: 1.3675578 | N22: 1.3905329 | O22: 1.413483 | P22: 1.4339748 | R22: =(J22/D22)^(1/6)-1 -> 0.017636078 | S22: =(P22/J22)^(1/6)-1 -> 0.014547705
A23: Growth rate (%) | C23: =C22/B22-1 -> 0.033944954 | D23: =D22/C22-1 -> 0.050576752 | E23: =E22/D22-1 -> 0.02027027 | F23: =F22/E22-1 -> -0.005794702 | G23: =G22/F22-1 -> 0.0066611157 | H23: =H22/G22-1 -> 0.038875103 | I23: =I22/H22-1 -> 0.035828025 | J23: =J22/I22-1 -> 0.010716555 | ... P23: =P22/O22-1 -> 0.014497362
A24: Number of all enterprises | B24: =B18+B20+B22 -> 323.912 | C24: =C18+C20+C22 -> 332.755 | D24: =D18+D20+D22 -> 316.562 | E24: =E18+E20+E22 -> 331.145 | F24: =F18+F20+F22 -> 330.625 | G24: =G18+G20+G22 -> 404.37 | H24: =H18+H20+H22 -> 407.709 | I24: =I18+I20+I22 -> 408.274 | ... P24: =P18+P20+P22 -> 441.78764 | R24: =(J24/D24)^(1/6)-1 -> 0.044421038 | S24: =(P24/J24)^(1/6)-1 -> 0.012162364
A25: Growth rate (%) | C25: =C24/B24-1 -> 0.027300625 | D25: =D24/C24-1 -> -0.048663431 | E25: =E24/D24-1 -> 0.046066805 | F25: =F24/E24-1 -> -0.0015703091 | G25: =G24/F24-1 -> 0.22304726 | H25: =H24/G24-1 -> 0.0082572891 | I25: =I24/H24-1 -> 0.0013857923 | J25: =J24/I24-1 -> 0.0063770537 | ... P25: =P24/O24-1 -> 0.0095934691
A27: Percentage of enterprises using cloud computing
A28: Percent of microenterprises using cloud computing | B28: 0.093093526 | C28: 0.10633418 | D28: 0.12120635 | E28: 0.13783776 | F28: 0.15634526 | G28: 0.17682809 | H28: 0.19936026 | I28: 0.22398235 | J28: 0.25069323 | K28: 0.27944245 | L28: 0.31012405 | M28: 0.34257279 | N28: 0.37656347 | O28: 0.41181415 | P28: 0.44799345
A29: Percent of SME using cloud computing | B29: 0.17472977 | C29: 0.20680555 | D29: 0.24303554 | E29: 0.28334532 | F29: 0.32744872 | G29: 0.37482648 | H29: 0.42473015 | I29: 0.47621687 | J29: 0.52821412 | K29: 0.57960628 | L29: 0.62932874 | M29: 0.6764531 | N29: 0.72024957 | O29: 0.76021903 | P29: 0.79609455
A30: Percent of large enterprises using cloud computing | B30: 0.31789668 | C30: 0.40648038 | D30: 0.50159636 | E30: 0.59659694 | F30: 0.68486608 | G30: 0.76154083 | H30: 0.82434478 | I30: 0.8733585 | J30: 0.91018582 | K30: 0.93707537 | L30: 0.95630094 | M30: 0.96984151 | N30: 0.97927732 | O30: 0.98580413 | P30: 0.99029562
A31: Percent of all enterprises using cloud computing | B31: 0.10418736 | C31: 0.11995785 | D31: 0.13825788 | E31: 0.15757533 | F31: 0.17825828 | G31: 0.19856415 | H31: 0.22509016 | I31: 0.25258275 | J31: 0.28171072 | K31: 0.31229085 | L31: 0.34441109 | M31: 0.37788078 | N31: 0.41242638 | O31: 0.44776407 | P31: 0.48350299
A33: Number of enterprises using cloud computing (thousands)
A34: Number of microenterprises using cloud computing | B34: =B28*B18 -> 26.234314 | C34: =C28*C18 -> 30.823513 | D34: =D28*D18 -> 33.303627 | E34: =E28*E18 -> 39.811268 | F34: =F28*F18 -> 45.463794 | G34: =G28*G18 -> 64.07189 | H34: =H28*H18 -> 72.445327 | I34: =I28*I18 -> 81.536072 | ... P34: =P28*P18 -> 178.0869 | R34: =(J34/D34)^(1/6)-1 -> 0.18442216 | S34: =(P34/J34)^(1/6)-1 -> 0.11647811
A35: Growth rate (%) | C35: =C34/B34-1 -> 0.17493116 | D35: =D34/C34-1 -> 0.080461748 | E35: =E34/D34-1 -> 0.19540336 | F35: =F34/E34-1 -> 0.14198309 | G35: =G34/F34-1 -> 0.40929482 | H35: =H34/G34-1 -> 0.13068815 | I35: =I34/H34-1 -> 0.12548422 | J35: =J34/I34-1 -> 0.12766704 | ... P35: =P34/O34-1 -> 0.099382566
A36: Number of SME using cloud computing | B36: =B29*B20 -> 7.1667162 | C36: =C29*C20 -> 8.6349588 | D36: =D29*D20 -> 9.8696734 | E36: =E29*E20 -> 11.648326 | F36: =F29*F20 -> 12.650326 | G36: =G29*G20 -> 15.300792 | H36: =H29*H20 -> 18.290579 | I36: =I29*I20 -> 20.450657 | ... P36: =P29*P20 -> 34.098689 | R36: =(J36/D36)^(1/6)-1 -> 0.14812081 | S36: =(P36/J36)^(1/6)-1 -> 0.070906518
A37: Growth rate (%) | C37: =C36/B36-1 -> 0.20486965 | D37: =D36/C36-1 -> 0.14299022 | E37: =E36/D36-1 -> 0.18021393 | F37: =F36/E36-1 -> 0.086020972 | G37: =G36/F36-1 -> 0.20951754 | H37: =H36/G36-1 -> 0.19540084 | I37: =I36/H36-1 -> 0.11809785 | J37: =J36/I36-1 -> 0.10540401 | ... P37: =P36/O36-1 -> 0.047405101
A38: Number of large enterprises using cloud computing | B38: =B30*B22 -> 0.34650739 | C38: =C30*C22 -> 0.45810339 | D38: =D30*D22 -> 0.59389009 | E38: =E30*E22 -> 0.72068911 | F38: =F30*F22 -> 0.82252416 | G38: =G30*G22 -> 0.92070286 | H38: =H30*H22 -> 1.035377 | I38: =I30*I22 -> 1.1362394 | ... P38: =P30*P22 -> 1.4200589 | R38: =(J38/D38)^(1/6)-1 -> 0.12388475 | S38: =(P38/J38)^(1/6)-1 -> 0.028912093
A39: Growth rate (%) | C39: =C38/B38-1 -> 0.32205951 | D39: =D38/C38-1 -> 0.29641061 | E39: =E38/D38-1 -> 0.21350586 | F39: =F38/E38-1 -> 0.14130234 | G39: =G38/F38-1 -> 0.1193627 | H39: =H38/G38-1 -> 0.12455069 | I39: =I38/H38-1 -> 0.097416069 | J39: =J38/I38-1 -> 0.053335921 | ... P39: =P38/O38-1 -> 0.01911959
A40: Number of all enterprises using cloud computing | B40: =B38+B36+B34 -> 33.747538 | C40: =C38+C36+C34 -> 39.916575 | D40: =D38+D36+D34 -> 43.767191 | E40: =E38+E36+E34 -> 52.180283 | F40: =F38+F36+F34 -> 58.936645 | G40: =G38+G36+G34 -> 80.293385 | H40: =H38+H36+H34 -> 91.771283 | I40: =I38+I36+I34 -> 103.12297 | ... P40: =P38+P36+P34 -> 213.60564 | R40: =(J40/D40)^(1/6)-1 -> 0.17596535 | S40: =(P40/J40)^(1/6)-1 -> 0.10751466
A41: Growth rate (%) | C41: =C40/B40-1 -> 0.18279964 | D41: =D40/C40-1 -> 0.09646657 | E41: =E40/D40-1 -> 0.19222372 | F41: =F40/E40-1 -> 0.12948113 | G41: =G40/F40-1 -> 0.36236776 | H41: =H40/G40-1 -> 0.14294949 | I41: =I40/H40-1 -> 0.1236954 | J41: =J40/I40-1 -> 0.12243299 | ... P41: =P40/O40-1 -> 0.090175588
A43: Total cloud computing market size (€ m) | B43: =B55+B111 -> 236.34883 | C43: =C55+C111 -> 288.21114 | D43: =D55+D111 -> 367.82254 | E43: =E55+E111 -> 479.91136 | F43: =F55+F111 -> 593.73796 | G43: =G55+G111 -> 726.42339 | H43: =H55+H111 -> 881.46151 | I43: =I55+I111 -> 1053.5603 | ... P43: =P55+P111 -> 3202.5393 | R43: =(J43/D43)^(1/6)-1 -> 0.22510458 | S43: =(P43/J43)^(1/6)-1 -> 0.17076444
A44: Growth rate (%) | C44: =C43/B43-1 -> 0.21943122 | D44: =D43/C43-1 -> 0.27622596 | E44: =E43/D43-1 -> 0.30473614 | F44: =F43/E43-1 -> 0.23718253 | G44: =G43/F43-1 -> 0.22347475 | H44: =H43/G43-1 -> 0.21342666 | I44: =I43/H43-1 -> 0.19524257 | J44: =J43/I43-1 -> 0.18036931 | ... P44: =P43/O43-1 -> 0.13263527
A46: Public cloud (by size of enterprises) (€ m)
A47: Microenterprises (0-9 employees) | B47: 5.180834 | C47: 6.5971936 | D47: 8.8687603 | E47: 12.20035 | F47: 15.960109 | G47: 20.456554 | H47: 25.93142 | I47: 32.477676 | J47: 40.001443 | K47: 48.579981 | L47: 61.037106 | M47: 77.181318 | N47: 93.444912 | O47: 110.68035 | P47: 129.12849 | R47: =(J47/D47)^(1/6)-1 -> 0.2853916 | S47: =(P47/J47)^(1/6)-1 -> 0.21569436
...

Sheet Greece
A1: Year | B1: 2016 | C1: 2017 | D1: 2018 | E1: 2019 | F1: 2020 | G1: 2021 | H1: 2022 | I1: 2023 | J1: 2024 | K1: 2025e | L1: 2026f | M1: 2027f | N1: 2028f | O1: 2029f | P1: 2030f | R1: CAGR 2019-2024 | S1: CAGR 2025-2030
A2: Total IT market size (€ m) | B2: =B4+B6+B8 -> 2727.7391 | C2: =C4+C6+C8 -> 2737.0821 | D2: =D4+D6+D8 -> 2806.2099 | E2: =E4+E6+E8 -> 2965.0213 | F2: =F4+F6+F8 -> 2885.1116 | G2: =G4+G6+G8 -> 3133.1404 | H2: =H4+H6+H8 -> 3325.2016 | I2: =I4+I6+I8 -> 3517.1896 | ... P2: =P4+P6+P8 -> 5171.278 | R2: =(J2/D2)^(1/6)-1 -> 0.05064238 | S2: =(P2/J2)^(1/6)-1 -> 0.053880513
A3: Growth rate (%) | C3: =C2/B2-1 -> 0.0034251868 | D3: =D2/C2-1 -> 0.025256004 | E3: =E2/D2-1 -> 0.056592857 | F3: =F2/E2-1 -> -0.026950821 | G3: =G2/F2-1 -> 0.085968534 | H3: =H2/G2-1 -> 0.061299925 | I3: =I2/H2-1 -> 0.057737233 | J3: =J2/I2-1 -> 0.07313377 | ... P3: =P2/O2-1 -> 0.054277271
A4: Software | B4: 521.04129 | C4: 538.44974 | D4: 558.50473 | E4: 587.84387 | F4: 596.43212 | G4: 643.8548 | H4: 685.77503 | I4: 737.54004 | J4: 804.33399 | K4: 855.66763 | L4: 908.18841 | M4: 962.55675 | N4: 1019.4732 | O4: 1082.7199 | P4: 1157.5208 | R4: =(J4/D4)^(1/6)-1 -> 0.062677768 | S4: =(P4/J4)^(1/6)-1 -> 0.062548419
A5: Growth rate (%) | C5: =C4/B4-1 -> 0.03341088 | D5: =D4/C4-1 -> 0.037245794 | E5: =E4/D4-1 -> 0.05253159 | F5: =F4/E4-1 -> 0.014609755 | G5: =G4/F4-1 -> 0.079510594 | H5: =H4/G4-1 -> 0.065108217 | I5: =I4/H4-1 -> 0.075483938 | J5: =J4/I4-1 -> 0.090563162 | ... P5: =P4/O4-1 -> 0.069086096
A6: Hardware | B6: 1380.6925 | C6: 1346.1261 | D6: 1366.4645 | E6: 1452.3599 | F6: 1380.0299 | G6: 1523.7014 | H6: 1612.465 | I6: 1680.8688 | J6: 1782.3117 | K6: 1889.8643 | L6: 1979.7906 | M6: 2052.1066 | N6: 2118.9245 | O6: 2181.8166 | P6: 2241.3357 | R6: =(J6/D6)^(1/6)-1 -> 0.045275769 | S6: =(P6/J6)^(1/6)-1 -> 0.038932202
A7: Growth rate (%) | C7: =C6/B6-1 -> -0.02503549 | D7: =D6/C6-1 -> 0.015108838 | E7: =E6/D6-1 -> 0.062859566 | F7: =F6/E6-1 -> -0.049801693 | G7: =G6/F6-1 -> 0.10410748 | H7: =H6/G6-1 -> 0.058255266 | I7: =I6/H6-1 -> 0.042421909 | J7: =J6/I6-1 -> 0.060351458 | ... P7: =P6/O6-1 -> 0.027279606
A8: Services | B8: 826.00536 | C8: 852.50624 | D8: 881.24061 | E8: 924.81754 | F8: 908.6495 | G8: 965.5842 | H8: 1026.9616 | I8: 1098.7807 | J8: 1187.7692 | K8: 1261.3537 | L8: 1343.2104 | M8: 1431.2711 | N8: 1528.8935 | O8: 1640.509 | P8: 1772.4215 | R8: =(J8/D8)^(1/6)-1 -> 0.051008574 | S8: =(P8/J8)^(1/6)-1 -> 0.068987168
A9: Growth rate (%) | C9: =C8/B8-1 -> 0.032083182 | D9: =D8/C8-1 -> 0.033705756 | E9: =E8/D8-1 -> 0.049449521 | F9: =F8/E8-1 -> -0.017482403 | G9: =G8/F8-1 -> 0.062658594 | H9: =H8/G8-1 -> 0.063565044 | I9: =I8/H8-1 -> 0.069933575 | J9: =J8/I8-1 -> 0.080988399 | ... P9: =P8/O8-1 -> 0.080409492
A11: Smartphones market size (€ m) | B11: 777.61218 | C11: 723.58729 | D11: 721.4392 | E11: 783.62138 | F11: 640.84104 | G11: 726.10836 | H11: 766.2204 | I11: 766.98022 | J11: 781.74003 | K11: 830.56107 | L11: 868.10775 | M11: 890.36439 | N11: 909.28828 | O11: 925.65397 | P11: 939.29992 | R11: =(J11/D11)^(1/6)-1 -> 0.013468924 | S11: =(P11/J11)^(1/6)-1 -> 0.031075156
A12: Growth rate (%) | C12: =C11/B11-1 -> -0.069475366 | D12: =D11/C11-1 -> -0.002968675 | E12: =E11/D11-1 -> 0.086191855 | F12: =F11/E11-1 -> -0.18220577 | G12: =G11/F11-1 -> 0.13305533 | H12: =H11/G11-1 -> 0.055242509 | I12: =I11/H11-1 -> 0.00099163621 | J12: =J11/I11-1 -> 0.019244061 | ... P12: =P11/O11-1 -> 0.014741964
A14: Cybersecurity market size (€ m) | B14: 77.913977 | C14: 79.337733 | D14: 90.948024 | E14: 93.649983 | F14: 98.444425 | G14: 107.62161 | H14: 120.14458 | I14: 132.8671 | J14: 146.82005 | K14: 157.14194 | L14: 166.97076 | M14: 176.15807 | N14: 184.58999 | O14: 193.18657 | P14: 203.62844 | R14: =(J14/D14)^(1/6)-1 -> 0.083091999 | S14: =(P14/J14)^(1/6)-1 -> 0.056028192
A15: Growth rate (%) | C15: =C14/B14-1 -> 0.018273429 | D15: =D14/C14-1 -> 0.14634009 | E15: =E14/D14-1 -> 0.029708823 | F15: =F14/E14-1 -> 0.051195338 | G15: =G14/F14-1 -> 0.093221997 | H15: =H14/G14-1 -> 0.11636105 | I15: =I14/H14-1 -> 0.10589344 | J15: =J14/I14-1 -> 0.10501432 | ... P15: =P14/O14-1 -> 0.054050661
A17: Enterprises (by size) (number of enterprises in thousands)
A18: Microenterprises (0-9 employees) | B18: 766.482 | C18: 688.217 | D18: 672.143 | E18: 677.62 | F18: 675.205 | G18: 696.658 | H18: 724.394 | I18: 745.385 | J18: 762.34373 | K18: 778.86783 | L18: 784.49209 | M18: 790.57506 | N18: 796.16874 | O18: 799.53314 | P18: 803.26351 | R18: =(J18/D18)^(1/6)-1 -> 0.021209529 | S18: =(P18/J18)^(1/6)-1 -> 0.0087522923
A19: Growth rate (%) | C19: =C18/B18-1 -> -0.10210938 | D19: =D18/C18-1 -> -0.023356005 | E19: =E18/D18-1 -> 0.0081485636 | F19: =F18/E18-1 -> -0.0035639444 | G19: =G18/F18-1 -> 0.031772573 | H19: =H18/G18-1 -> 0.039812935 | I19: =I18/H18-1 -> 0.028977324 | J19: =J18/I18-1 -> 0.022751634 | ... P19: =P18/O18-1 -> 0.0046656811
A20: SME (10-249 employees) | B20: 32.846841 | C20: 34.45385 | D20: 36.033 | E20: 39.534 | F20: 35.505 | G20: 39.0935 | H20: 42.682 | I20: 45.33 | J20: 47.066775 | K20: 48.688301 | L20: 50.28446 | M20: 51.722301 | N20: 53.003003 | O20: 54.279035 | P20: 55.447471 | R20: =(J20/D20)^(1/6)-1 -> 0.045528005 | S20: =(P20/J20)^(1/6)-1 -> 0.027687836
A21: Growth rate (%) | C21: =C20/B20-1 -> 0.048924313 | D21: =D20/C20-1 -> 0.045833775 | E21: =E20/D20-1 -> 0.097160936 | F21: =F20/E20-1 -> -0.10191228 | G21: =G20/F20-1 -> 0.10107027 | H21: =H20/G20-1 -> 0.091792753 | I21: =I20/H20-1 -> 0.062040204 | J21: =J20/I20-1 -> 0.038314032 | ... P21: =P20/O20-1 -> 0.021526469
A22: Large enterprises (250+ employees) | B22: 0.51744444 | C22: 0.50333333 | D22: 0.523 | E22: 0.526 | F22: 0.461 | G22: 0.504 | H22: 0.547 | I22: 0.59 | J22: 0.60244642 | K22: 0.61186497 | L22: 0.62190009 | M22: 0.63020181 | N22: 0.63450728 | O22: 0.63913669 | P22: 0.63986116 | R22: =(J22/D22)^(1/6)-1 -> 0.023849503 | S22: =(P22/J22)^(1/6)-1 -> 0.010092671
A23: Growth rate (%) | C23: =C22/B22-1 -> -0.027270775 | D23: =D22/C22-1 -> 0.039072848 | E23: =E22/D22-1 -> 0.0057361377 | F23: =F22/E22-1 -> -0.12357414 | G23: =G22/F22-1 -> 0.093275488 | H23: =H22/G22-1 -> 0.08531746 | I23: =I22/H22-1 -> 0.078610603 | J23: =J22/I22-1 -> 0.021095634 | ... P23: =P22/O22-1 -> 0.0011335153
A24: Number of all enterprises | B24: =B18+B20+B22 -> 799.84629 | C24: =C18+C20+C22 -> 723.17418 | D24: =D18+D20+D22 -> 708.699 | E24: =E18+E20+E22 -> 717.68 | F24: =F18+F20+F22 -> 711.171 | G24: =G18+G20+G22 -> 736.2555 | H24: =H18+H20+H22 -> 767.623 | I24: =I18+I20+I22 -> 791.305 | ... P24: =P18+P20+P22 -> 859.35084 | R24: =(J24/D24)^(1/6)-1 -> 0.022519715 | S24: =(P24/J24)^(1/6)-1 -> 0.0099032215
A25: Growth rate (%) | C25: =C24/B24-1 -> -0.095858546 | D25: =D24/C24-1 -> -0.020016178 | E25: =E24/D24-1 -> 0.012672517 | F25: =F24/E24-1 -> -0.0090695017 | G25: =G24/F24-1 -> 0.035272108 | H25: =H24/G24-1 -> 0.042604096 | I25: =I24/H24-1 -> 0.030851082 | J25: =J24/I24-1 -> 0.023641893 | ... P25: =P24/O24-1 -> 0.0057341208
A27: Percentage of enterprises using cloud computing
A28: Percent of microenterprises using cloud computing | B28: 0.04865747 | C28: 0.056671316 | D28: 0.065913589 | E28: 0.076540844 | F28: 0.088718792 | G28: 0.10261899 | H28: 0.11841403 | I28: 0.13627106 | J28: 0.15634339 | K28: 0.17876041 | L28: 0.2036159 | M28: 0.23095546 | N28: 0.26076394 | O28: 0.29295414 | P28: 0.32735836
A29: Percent of SME using cloud computing | B29: 0.093268565 | C29: 0.10752675 | D29: 0.12366734 | E29: 0.14184568 | F29: 0.16220155 | G29: 0.18484938 | H29: 0.20986734 | I29: 0.23728565 | J29: 0.26707525 | K29: 0.29913795 | L29: 0.33329939 | M29: 0.36930638 | N29: 0.4068296 | O29: 0.44547248 | P29: 0.48478604
A30: Percent of large enterprises using cloud computing | B30: 0.35214962 | C30: 0.38151522 | D30: 0.41177316 | E30: 0.4427131 | F30: 0.47410408 | G30: 0.50570109 | H30: 0.53725263 | I30: 0.56850862 | J30: 0.5992283 | K30: 0.62918745 | L30: 0.65818454 | M30: 0.68604555 | N30: 0.71262716 | O30: 0.73781828 | P30: 0.76154007
A31: Percent of all enterprises using cloud computing | B31: 0.050685827 | C31: 0.059320291 | D31: 0.069105248 | E31: 0.08040659 | F31: 0.092637214 | G31: 0.10726116 | H31: 0.12379755 | I31: 0.14237997 | J31: 0.16310699 | K31: 0.18617023 | L31: 0.21176023 | M31: 0.23978496 | N31: 0.27021154 | O31: 0.30297563 | P31: 0.33783928
A33: Number of enterprises using cloud computing (thousands)
A34: Number of microenterprises using cloud computing | B34: =B28*B18 -> 37.295075 | C34: =C28*C18 -> 39.002163 | D34: =D28*D18 -> 44.303358 | E34: =E28*E18 -> 51.865607 | F34: =F28*F18 -> 59.903372 | G34: =G28*G18 -> 71.49034 | H34: =H28*H18 -> 85.778415 | I34: =I28*I18 -> 101.5744 | ... P34: =P28*P18 -> 262.95503 | R34: =(J34/D34)^(1/6)-1 -> 0.17932168 | S34: =(P34/J34)^(1/6)-1 -> 0.14097253
A35: Growth rate (%) | C35: =C34/B34-1 -> 0.045772488 | D35: =D34/C34-1 -> 0.13592052 | E35: =E34/D34-1 -> 0.17069246 | F35: =F34/E34-1 -> 0.15497293 | G35: =G34/F34-1 -> 0.19342763 | H35: =H34/G34-1 -> 0.19986023 | I35: =I34/H34-1 -> 0.18414874 | J35: =J34/I34-1 -> 0.17339997 | ... P35: =P34/O34-1 -> 0.12265257
A36: Number of SME using cloud computing | B36: =B29*B20 -> 3.0635777 | C36: =C29*C20 -> 3.7047106 | D36: =D29*D20 -> 4.4561053 | E36: =E29*E20 -> 5.6077273 | F36: =F29*F20 -> 5.7589659 | G36: =G29*G20 -> 7.2264093 | H36: =H29*H20 -> 8.9575578 | I36: =I29*I20 -> 10.756158 | ... P36: =P29*P20 -> 26.88016 | R36: =(J36/D36)^(1/6)-1 -> 0.18868132 | S36: =(P36/J36)^(1/6)-1 -> 0.1350473
A37: Growth rate (%) | C37: =C36/B36-1 -> 0.20927588 | D37: =D36/C36-1 -> 0.20282143 | E37: =E36/D36-1 -> 0.25843687 | F37: =F36/E36-1 -> 0.02696969 | G37: =G36/F36-1 -> 0.25481023 | H37: =H36/G36-1 -> 0.2395586 | I37: =I36/H36-1 -> 0.2007914 | J37: =J36/I36-1 -> 0.16866731 | ... P37: =P36/O36-1 -> 0.11167758
A38: Number of large enterprises using cloud computing | B38: =B30*B22 -> 0.18221787 | C38: =C30*C22 -> 0.19202933 | D38: =D30*D22 -> 0.21535736 | E38: =E30*E22 -> 0.23286709 | F38: =F30*F22 -> 0.21856198 | G38: =G30*G22 -> 0.25487335 | H38: =H30*H22 -> 0.29387719 | I38: =I30*I22 -> 0.33542009 | ... P38: =P30*P22 -> 0.48727992 | R38: =(J38/D38)^(1/6)-1 -> 0.089913012 | S38: =(P38/J38)^(1/6)-1 -> 0.051262793
A39: Growth rate (%) | C39: =C38/B38-1 -> 0.053844682 | D39: =D38/C38-1 -> 0.12148163 | E39: =E38/D38-1 -> 0.08130546 | F39: =F38/E38-1 -> -0.06143037 | G39: =G38/F38-1 -> 0.16613763 | H39: =H38/G38-1 -> 0.15303223 | I39: =I38/H38-1 -> 0.14136143 | J39: =J38/I38-1 -> 0.076271112 | ... P39: =P38/O38-1 -> 0.033321223
A40: Number of all enterprises using cloud computing | B40: =B38+B36+B34 -> 40.54087 | C40: =C38+C36+C34 -> 42.898903 | D40: =D38+D36+D34 -> 48.97482 | E40: =E38+E36+E34 -> 57.706201 | F40: =F38+F36+F34 -> 65.8809 | G40: =G38+G36+G34 -> 78.971622 | H40: =H38+H36+H34 -> 95.02985 | I40: =I38+I36+I34 -> 112.66598 | ... P40: =P38+P36+P34 -> 290.32247 | R40: =(J40/D40)^(1/6)-1 -> 0.17986399 | S40: =(P40/J40)^(1/6)-1 -> 0.14021308
A41: Growth rate (%) | C41: =C40/B40-1 -> 0.058164335 | D41: =D40/C40-1 -> 0.14163339 | E41: =E40/D40-1 -> 0.17828306 | F41: =F40/E40-1 -> 0.14166066 | G41: =G40/F40-1 -> 0.19870284 | H41: =H40/G40-1 -> 0.20334175 | I41: =I40/H40-1 -> 0.18558517 | J41: =J40/I40-1 -> 0.17265898 | ... P41: =P40/O40-1 -> 0.12146476
A43: Total cloud computing market size (€ m) | B43: =B55+B111 -> 50.476796 | C43: =C55+C111 -> 68.40563 | D43: =D55+D111 -> 85.198035 | E43: =E55+E111 -> 107.89146 | F43: =F55+F111 -> 128.59975 | G43: =G55+G111 -> 172.19197 | H43: =H55+H111 -> 232.87161 | I43: =I55+I111 -> 291.5586 | ... P43: =P55+P111 -> 1068.5902 | R43: =(J43/D43)^(1/6)-1 -> 0.27069197 | S43: =(P43/J43)^(1/6)-1 -> 0.1995637
A44: Growth rate (%) | C44: =C43/B43-1 -> 0.35518962 | D44: =D43/C43-1 -> 0.24548279 | E44: =E43/D43-1 -> 0.26636084 | F44: =F43/E43-1 -> 0.19193638 | G44: =G43/F43-1 -> 0.33897592 | H44: =H43/G43-1 -> 0.35239528 | I44: =I43/H43-1 -> 0.25201438 | J44: =J43/I43-1 -> 0.23011422 | ... P44: =P43/O43-1 -> 0.18112812
A46: Public cloud (by size of enterprises) (€ m)
A47: Microenterprises (0-9 employees) | B47: 2.9466189 | C47: 4.0856428 | D47: 6.9167891 | E47: 8.798452 | F47: 13.441948 | G47: 19.441939 | H47: 29.293594 | I47: 38.17877 | J47: 48.782861 | K47: 65.304932 | L47: 84.901724 | M47: 108.13611 | N47: 139.72454 | O47: 178.69843 | P47: 223.22833 | R47: =(J47/D47)^(1/6)-1 -> 0.38482147 | S47: =(P47/J47)^(1/6)-1 -> 0.28848789
...

Sheet Czech Republic
A1: Year | B1: 2016 | C1: 2017 | D1: 2018 | E1: 2019 | F1: 2020 | G1: 2021 | H1: 2022 | I1: 2023 | J1: 2024 | K1: 2025e | L1: 2026f | M1: 2027f | N1: 2028f | O1: 2029f | P1: 2030f | R1: CAGR 2019-2024 | S1: CAGR 2025-2030
A2: Total IT market size (€ m) | B2: =B4+B6+B8 -> 5099.4372 | C2: =C4+C6+C8 -> 5299.258 | D2: =D4+D6+D8 -> 5507.3186 | E2: =E4+E6+E8 -> 5840.0348 | F2: =F4+F6+F8 -> 6019.9458 | G2: =G4+G6+G8 -> 6439.378 | H2: =H4+H6+H8 -> 6804.8176 | I2: =I4+I6+I8 -> 7327.0026 | ... P2: =P4+P6+P8 -> 11004.718 | R2: =(J2/D2)^(1/6)-1 -> 0.062174429 | S2: =(P2/J2)^(1/6)-1 -> 0.056600009
